<?xml version="1.0" encoding="UTF-8"?>
<!-- Generated by org.testng.reporters.JUnitXMLReporter -->
<testsuite hostname="Lex-Desktop" name="Yahoo" tests="5" failures="4" timestamp="22 Jul 2014 18:57:47 GMT" time="20.461" errors="0">
  <testcase name="login_01" time="13.352" classname="testcases.loginTest"/>
  <testcase name="test1" time="0.001" classname="testcases.VerifyTest">
    <failure type="java.lang.Throwable" message="Multiple failures (3):

Failure 1 of 3:
java.lang.AssertionError: expected [true] but found [false]
	at org.testng.Assert.fail(Assert.java:94)
	at org.testng.Assert.failNotEquals(Assert.java:494)
	at org.testng.Assert.assertTrue(Assert.java:42)
	at org.testng.Assert.assertTrue(Assert.java:52)
	at utils.TestBase.assertTrue(TestBase.java:19)
	at utils.TestBase.verifyTrue(TestBase.java:53)
	at testcases.VerifyTest.test1(VerifyTest.java:11)
	at sun.reflect.NativeMethodAccessorImpl.invoke0(Native Method)
	at sun.reflect.NativeMethodAccessorImpl.invoke(Unknown Source)
	at sun.reflect.DelegatingMethodAccessorImpl.invoke(Unknown Source)
	at java.lang.reflect.Method.invoke(Unknown Source)
	at org.testng.internal.MethodInvocationHelper.invokeMethod(MethodInvocationHelper.java:84)
	at org.testng.internal.Invoker.invokeMethod(Invoker.java:714)
	at org.testng.internal.Invoker.invokeTestMethod(Invoker.java:901)
	at org.testng.internal.Invoker.invokeTestMethods(Invoker.java:1231)
	at org.testng.internal.TestMethodWorker.invokeTestMethods(TestMethodWorker.java:127)
	at org.testng.internal.TestMethodWorker.run(TestMethodWorker.java:111)
	at org.testng.TestRunner.privateRun(TestRunner.java:767)
	at org.testng.TestRunner.run(TestRunner.java:617)
	at org.testng.SuiteRunner.runTest(SuiteRunner.java:334)
	at org.testng.SuiteRunner.runSequentially(SuiteRunner.java:329)
	at org.testng.SuiteRunner.privateRun(SuiteRunner.java:291)
	at org.testng.SuiteRunner.run(SuiteRunner.java:240)
	at org.testng.SuiteRunnerWorker.runSuite(SuiteRunnerWorker.java:52)
	at org.testng.SuiteRunnerWorker.run(SuiteRunnerWorker.java:86)
	at org.testng.TestNG.runSuitesSequentially(TestNG.java:1224)
	at org.testng.TestNG.runSuitesLocally(TestNG.java:1149)
	at org.testng.TestNG.run(TestNG.java:1057)
	at org.testng.remote.RemoteTestNG.run(RemoteTestNG.java:111)
	at org.testng.remote.RemoteTestNG.initAndRun(RemoteTestNG.java:204)
	at org.testng.remote.RemoteTestNG.main(RemoteTestNG.java:175)


Failure 2 of 3:
java.lang.AssertionError: expected [fail] but found [pass]
	at org.testng.Assert.fail(Assert.java:94)
	at org.testng.Assert.failNotEquals(Assert.java:494)
	at org.testng.Assert.assertEquals(Assert.java:123)
	at org.testng.Assert.assertEquals(Assert.java:165)
	at utils.TestBase.assertEquals(TestBase.java:39)
	at utils.TestBase.verifyEquals(TestBase.java:93)
	at testcases.VerifyTest.test1(VerifyTest.java:12)
	at sun.reflect.NativeMethodAccessorImpl.invoke0(Native Method)
	at sun.reflect.NativeMethodAccessorImpl.invoke(Unknown Source)
	at sun.reflect.DelegatingMethodAccessorImpl.invoke(Unknown Source)
	at java.lang.reflect.Method.invoke(Unknown Source)
	at org.testng.internal.MethodInvocationHelper.invokeMethod(MethodInvocationHelper.java:84)
	at org.testng.internal.Invoker.invokeMethod(Invoker.java:714)
	at org.testng.internal.Invoker.invokeTestMethod(Invoker.java:901)
	at org.testng.internal.Invoker.invokeTestMethods(Invoker.java:1231)
	at org.testng.internal.TestMethodWorker.invokeTestMethods(TestMethodWorker.java:127)
	at org.testng.internal.TestMethodWorker.run(TestMethodWorker.java:111)
	at org.testng.TestRunner.privateRun(TestRunner.java:767)
	at org.testng.TestRunner.run(TestRunner.java:617)
	at org.testng.SuiteRunner.runTest(SuiteRunner.java:334)
	at org.testng.SuiteRunner.runSequentially(SuiteRunner.java:329)
	at org.testng.SuiteRunner.privateRun(SuiteRunner.java:291)
	at org.testng.SuiteRunner.run(SuiteRunner.java:240)
	at org.testng.SuiteRunnerWorker.runSuite(SuiteRunnerWorker.java:52)
	at org.testng.SuiteRunnerWorker.run(SuiteRunnerWorker.java:86)
	at org.testng.TestNG.runSuitesSequentially(TestNG.java:1224)
	at org.testng.TestNG.runSuitesLocally(TestNG.java:1149)
	at org.testng.TestNG.run(TestNG.java:1057)
	at org.testng.remote.RemoteTestNG.run(RemoteTestNG.java:111)
	at org.testng.remote.RemoteTestNG.initAndRun(RemoteTestNG.java:204)
	at org.testng.remote.RemoteTestNG.main(RemoteTestNG.java:175)


Failure 3 of 3:
java.lang.AssertionError: expected [false] but found [true]">
      <![CDATA[java.lang.Throwable: Multiple failures (3):

Failure 1 of 3:
java.lang.AssertionError: expected [true] but found [false]
	at utils.TestBase.assertTrue(TestBase.java:19)
	at utils.TestBase.verifyTrue(TestBase.java:53)
	at testcases.VerifyTest.test1(VerifyTest.java:11)


Failure 2 of 3:
java.lang.AssertionError: expected [fail] but found [pass]
	at utils.TestBase.assertEquals(TestBase.java:39)
	at utils.TestBase.verifyEquals(TestBase.java:93)
	at testcases.VerifyTest.test1(VerifyTest.java:12)


Failure 3 of 3:
java.lang.AssertionError: expected [false] but found [true]
	at utils.TestBase.assertFalse(TestBase.java:27)
	at utils.TestBase.verifyFalse(TestBase.java:69)
	at testcases.VerifyTest.test1(VerifyTest.java:13)
... Removed 84 stack frames]]>
    </failure>
  </testcase> <!-- test1 -->
  <testcase name="test2" time="0.002" classname="testcases.VerifyTest">
    <failure type="java.lang.Throwable" message="Multiple failures (2):

Failure 1 of 2:
java.lang.AssertionError: expected [true] but found [false]
	at org.testng.Assert.fail(Assert.java:94)
	at org.testng.Assert.failNotEquals(Assert.java:494)
	at org.testng.Assert.assertTrue(Assert.java:42)
	at org.testng.Assert.assertTrue(Assert.java:52)
	at utils.TestBase.assertTrue(TestBase.java:19)
	at utils.TestBase.verifyTrue(TestBase.java:53)
	at testcases.VerifyTest.test2(VerifyTest.java:18)
	at sun.reflect.NativeMethodAccessorImpl.invoke0(Native Method)
	at sun.reflect.NativeMethodAccessorImpl.invoke(Unknown Source)
	at sun.reflect.DelegatingMethodAccessorImpl.invoke(Unknown Source)
	at java.lang.reflect.Method.invoke(Unknown Source)
	at org.testng.internal.MethodInvocationHelper.invokeMethod(MethodInvocationHelper.java:84)
	at org.testng.internal.Invoker.invokeMethod(Invoker.java:714)
	at org.testng.internal.Invoker.invokeTestMethod(Invoker.java:901)
	at org.testng.internal.Invoker.invokeTestMethods(Invoker.java:1231)
	at org.testng.internal.TestMethodWorker.invokeTestMethods(TestMethodWorker.java:127)
	at org.testng.internal.TestMethodWorker.run(TestMethodWorker.java:111)
	at org.testng.TestRunner.privateRun(TestRunner.java:767)
	at org.testng.TestRunner.run(TestRunner.java:617)
	at org.testng.SuiteRunner.runTest(SuiteRunner.java:334)
	at org.testng.SuiteRunner.runSequentially(SuiteRunner.java:329)
	at org.testng.SuiteRunner.privateRun(SuiteRunner.java:291)
	at org.testng.SuiteRunner.run(SuiteRunner.java:240)
	at org.testng.SuiteRunnerWorker.runSuite(SuiteRunnerWorker.java:52)
	at org.testng.SuiteRunnerWorker.run(SuiteRunnerWorker.java:86)
	at org.testng.TestNG.runSuitesSequentially(TestNG.java:1224)
	at org.testng.TestNG.runSuitesLocally(TestNG.java:1149)
	at org.testng.TestNG.run(TestNG.java:1057)
	at org.testng.remote.RemoteTestNG.run(RemoteTestNG.java:111)
	at org.testng.remote.RemoteTestNG.initAndRun(RemoteTestNG.java:204)
	at org.testng.remote.RemoteTestNG.main(RemoteTestNG.java:175)


Failure 2 of 2:
java.lang.AssertionError: expected [fail] but found [pass]">
      <![CDATA[java.lang.Throwable: Multiple failures (2):

Failure 1 of 2:
java.lang.AssertionError: expected [true] but found [false]
	at utils.TestBase.assertTrue(TestBase.java:19)
	at utils.TestBase.verifyTrue(TestBase.java:53)
	at testcases.VerifyTest.test2(VerifyTest.java:18)


Failure 2 of 2:
java.lang.AssertionError: expected [fail] but found [pass]
	at utils.TestBase.assertEquals(TestBase.java:39)
	at testcases.VerifyTest.test2(VerifyTest.java:19)
... Removed 56 stack frames]]>
    </failure>
  </testcase> <!-- test2 -->
  <testcase name="test3" time="0.0" classname="testcases.VerifyTest">
    <failure type="java.lang.AssertionError" message="expected [true] but found [false]">
      <![CDATA[java.lang.AssertionError: expected [true] but found [false]
	at utils.TestBase.assertTrue(TestBase.java:19)
	at utils.TestBase.verifyTrue(TestBase.java:53)
	at testcases.VerifyTest.test3(VerifyTest.java:26)
... Removed 28 stack frames]]>
    </failure>
  </testcase> <!-- test3 -->
  <testcase name="test4" time="0.0" classname="testcases.VerifyTest">
    <failure type="java.lang.AssertionError" message="expected [true] but found [false]">
      <![CDATA[java.lang.AssertionError: expected [true] but found [false]
	at utils.TestBase.assertTrue(TestBase.java:19)
	at testcases.VerifyTest.test4(VerifyTest.java:33)
... Removed 28 stack frames]]>
    </failure>
  </testcase> <!-- test4 -->
</testsuite> <!-- Yahoo -->
